<?xml version="1.0" ?>
<!-- =================================================================================== -->
<!-- |    This document was autogenerated by xacro from /opt/ros/kinetic/share/moveit_resources/panda_description/urdf/panda.urdf | -->
<!-- |    EDITING THIS FILE BY HAND IS NOT RECOMMENDED                                 | -->
<!-- =================================================================================== -->
<robot name="panda" xmlns:xacro="http://www.ros.org/wiki/xacro">
    <link name="panda_link_0">
        <visual>
            <geometry>
                <mesh filename="package://moveit_resources_panda_description/meshes/visual/link0.dae" />
            </geometry>
        </visual>
        <collision>
            <geometry>
                <mesh filename="package://moveit_resources_panda_description/meshes/collision/link0.stl" />
            </geometry>
        </collision>
    </link>
    <link name="panda_link_1">
        <visual>
            <geometry>
                <mesh filename="package://moveit_resources_panda_description/meshes/visual/link1.dae" />
            </geometry>
        </visual>
        <collision>
            <geometry>
                <mesh filename="package://moveit_resources_panda_description/meshes/collision/link1.stl" />
            </geometry>
        </collision>
    </link>
    <joint name="panda_joint_1" type="revolute">
        <safety_controller k_position="100.0" k_velocity="40.0" soft_lower_limit="-4.8973" soft_upper_limit="5.8973" />
        <origin rpy="0 0 0" xyz="0 0 0.333" />
        <parent link="panda_link_0" />
        <child link="panda_link_1" />
        <axis xyz="0 0 1" />
        <limit effort="87" lower="-2.9671" upper="2.9671" velocity="2.3925" />
    </joint>
    <link name="panda_link_2">
        <visual>
            <geometry>
                <mesh filename="package://moveit_resources_panda_description/meshes/visual/link2.dae" />
            </geometry>
        </visual>
        <collision>
            <geometry>
                <mesh filename="package://moveit_resources_panda_description/meshes/collision/link2.stl" />
            </geometry>
        </collision>
    </link>
    <joint name="panda_joint_2" type="revolute">
        <safety_controller k_position="100.0" k_velocity="40.0" soft_lower_limit="-2.7628" soft_upper_limit="2.7628" />
        <origin rpy="-1.57079632679 0 0" xyz="0 0 0" />
        <parent link="panda_link_1" />
        <child link="panda_link_2" />
        <axis xyz="0 0 1" />
        <limit effort="87" lower="-1.8326" upper="1.8326" velocity="2.3925" />
    </joint>
    <link name="panda_link_3">
        <visual>
            <geometry>
                <mesh filename="package://moveit_resources_panda_description/meshes/visual/link3.dae" />
            </geometry>
        </visual>
        <collision>
            <geometry>
                <mesh filename="package://moveit_resources_panda_description/meshes/collision/link3.stl" />
            </geometry>
        </collision>
    </link>
    <joint name="panda_joint_3" type="revolute">
        <safety_controller k_position="100.0" k_velocity="40.0" soft_lower_limit="-2.8973" soft_upper_limit="2.8973" />
        <origin rpy="1.57079632679 0 0" xyz="0 -0.316 0" />
        <parent link="panda_link_2" />
        <child link="panda_link_3" />
        <axis xyz="0 0 1" />
        <limit effort="87" lower="-2.9671" upper="2.9671" velocity="2.3925" />
    </joint>
    <link name="panda_link_4">
        <visual>
            <geometry>
                <mesh filename="package://moveit_resources_panda_description/meshes/visual/link4.dae" />
            </geometry>
        </visual>
        <collision>
            <geometry>
                <mesh filename="package://moveit_resources_panda_description/meshes/collision/link4.stl" />
            </geometry>
        </collision>
    </link>
    <joint name="panda_joint_4" type="revolute">
        <safety_controller k_position="100.0" k_velocity="40.0" soft_lower_limit="-3.0718" soft_upper_limit="3.0175" />
        <origin rpy="1.57079632679 0 0" xyz="0.0825 0 0" />
        <parent link="panda_link_3" />
        <child link="panda_link_4" />
        <axis xyz="0 0 1" />
        <limit effort="87" lower="-3.1416" upper="0.0873" velocity="2.3925" />
    </joint>
    <link name="panda_link_5">
        <visual>
            <geometry>
                <mesh filename="package://moveit_resources_panda_description/meshes/visual/link5.dae" />
            </geometry>
        </visual>
        <collision>
            <geometry>
                <mesh filename="package://moveit_resources_panda_description/meshes/collision/link5.stl" />
            </geometry>
        </collision>
    </link>
    <joint name="panda_joint_5" type="revolute">
        <safety_controller k_position="100.0" k_velocity="40.0" soft_lower_limit="-2.8973" soft_upper_limit="2.8973" />
        <origin rpy="-1.57079632679 0 0" xyz="-0.0825 0.384 0" />
        <parent link="panda_link_4" />
        <child link="panda_link_5" />
        <axis xyz="0 0 1" />
        <limit effort="12" lower="-2.9671" upper="2.9671" velocity="2.8710" />
    </joint>
    <link name="panda_link_6">
        <visual>
            <geometry>
                <mesh filename="package://moveit_resources_panda_description/meshes/visual/link6.dae" />
            </geometry>
        </visual>
        <collision>
            <geometry>
                <mesh filename="package://moveit_resources_panda_description/meshes/collision/link6.stl" />
            </geometry>
        </collision>
    </link>
    <joint name="panda_joint_6" type="revolute">
        <safety_controller k_position="100.0" k_velocity="40.0" soft_lower_limit="-3.0175" soft_upper_limit="3.7525" />
        <origin rpy="1.57079632679 0 0" xyz="0 0 0" />
        <parent link="panda_link_5" />
        <child link="panda_link_6" />
        <axis xyz="0 0 1" />
        <limit effort="12" lower="-0.0873" upper="3.8223" velocity="2.8710" />
    </joint>
    <link name="panda_link_7">
        <visual>
            <geometry>
                <mesh filename="package://moveit_resources_panda_description/meshes/visual/link7.dae" />
            </geometry>
        </visual>
        <collision>
            <geometry>
                <mesh filename="package://moveit_resources_panda_description/meshes/collision/link7.stl" />
            </geometry>
        </collision>
    </link>
    <joint name="panda_joint_7" type="revolute">
        <safety_controller k_position="100.0" k_velocity="40.0" soft_lower_limit="-2.8973" soft_upper_limit="2.8973" />
        <origin rpy="1.57079632679 0 0" xyz="0.088 0 0" />
        <parent link="panda_link_6" />
        <child link="panda_link_7" />
        <axis xyz="0 0 1" />
        <limit effort="12" lower="-2.9671" upper="2.9671" velocity="2.8710" />
    </joint>
    <link name="panda_link_ee" />
    <joint name="panda_joint_8" type="fixed">
        <origin rpy="0 0 0" xyz="0 0 0.107" />
        <parent link="panda_link_7" />
        <child link="panda_link_ee" />
        <axis xyz="0 0 0" />
    </joint>

</robot>
