<?xml version="1.0" ?>
<!-- =================================================================================== -->
<!-- |    This document was autogenerated by xacro from /home/lijiaqian/ws/prak_ros1_ws/src/hera_description/urdf/hera_main.urdf.xacro | -->
<!-- |    EDITING THIS FILE BY HAND IS NOT RECOMMENDED                                 | -->
<!-- =================================================================================== -->
<robot name="hera_operating_theatre">
  <!--<xacro:include filename="$(find hera_description)/urdf/pig_phantom/pig_phantom.xacro"/>-->
  <link name="world"/>
  <!--joint between {parent} and link_0-->
  <joint name="world_panda_joint" type="fixed">
    <origin rpy="0 0 0" xyz="0 0 0"/>
    <parent link="world"/>
    <child link="panda_link_0"/>
    <dynamics damping="1.0"/>
  </joint>
  <!-- link 0 -->
  <link name="panda_link_0">
    <visual>
      <geometry>
        <mesh filename="package://hera_description/meshes/panda/visual/link0.dae"/>
      </geometry>
    </visual>
    <collision>
      <geometry>
        <mesh filename="package://hera_description/meshes/panda/collision/link0.stl"/>
      </geometry>
    </collision>
    <inertial>
      <origin rpy="0 0 0" xyz="0 0 0"/>
      <mass value="3.06"/>
      <inertia ixx="0.3" ixy="0.0" ixz="0.0" iyy="0.3" iyz="0.0" izz="0.3"/>
    </inertial>
  </link>
  <!-- joint between link 0 and link 1 -->
  <joint name="panda_joint_1" type="revolute">
    <safety_controller k_position="100.0" k_velocity="40.0" soft_lower_limit="-2.8973" soft_upper_limit="2.8973"/>
    <origin rpy="0 0 0" xyz="0 0 0.333"/>
    <parent link="panda_link_0"/>
    <child link="panda_link_1"/>
    <axis xyz="0 0 1"/>
    <limit effort="87" lower="-2.8973" upper="2.8973" velocity="2.1750"/>
    <dynamics damping="1.0"/>
  </joint>
  <!-- link 1 -->
  <link name="panda_link_1">
    <visual>
      <geometry>
        <mesh filename="package://hera_description/meshes/panda/visual/link1.dae"/>
      </geometry>
    </visual>
    <collision>
      <geometry>
        <mesh filename="package://hera_description/meshes/panda/collision/link1.stl"/>
      </geometry>
    </collision>
    <inertial>
      <origin rpy="0 0 0" xyz="0 0 0"/>
      <mass value="2.34"/>
      <inertia ixx="0.3" ixy="0.0" ixz="0.0" iyy="0.3" iyz="0.0" izz="0.3"/>
    </inertial>
  </link>
  <!-- joint between link 1 and link 2 -->
  <joint name="panda_joint_2" type="revolute">
    <safety_controller k_position="100.0" k_velocity="40.0" soft_lower_limit="-1.7628" soft_upper_limit="1.7628"/>
    <origin rpy="-1.5707963267948966 0 0" xyz="0 0 0"/>
    <parent link="panda_link_1"/>
    <child link="panda_link_2"/>
    <axis xyz="0 0 1"/>
    <limit effort="87" lower="-1.7628" upper="1.7628" velocity="2.1750"/>
    <dynamics damping="1.0"/>
  </joint>
  <!-- link 2 -->
  <link name="panda_link_2">
    <visual>
      <geometry>
        <mesh filename="package://hera_description/meshes/panda/visual/link2.dae"/>
      </geometry>
    </visual>
    <collision>
      <geometry>
        <mesh filename="package://hera_description/meshes/panda/collision/link2.stl"/>
      </geometry>
    </collision>
    <inertial>
      <origin rpy="0 0 0" xyz="0 0 0"/>
      <mass value="2.36"/>
      <inertia ixx="0.3" ixy="0.0" ixz="0.0" iyy="0.3" iyz="0.0" izz="0.3"/>
    </inertial>
  </link>
  <!-- joint between link 2 and link 3 -->
  <joint name="panda_joint_3" type="revolute">
    <safety_controller k_position="100.0" k_velocity="40.0" soft_lower_limit="-2.8973" soft_upper_limit="2.8973"/>
    <origin rpy="1.5707963267948966 0 0" xyz="0 -0.316 0"/>
    <parent link="panda_link_2"/>
    <child link="panda_link_3"/>
    <axis xyz="0 0 1"/>
    <limit effort="87" lower="-2.8973" upper="2.8973" velocity="2.1750"/>
    <dynamics damping="1.0"/>
  </joint>
  <!-- link 3 -->
  <link name="panda_link_3">
    <visual>
      <geometry>
        <mesh filename="package://hera_description/meshes/panda/visual/link3.dae"/>
      </geometry>
    </visual>
    <collision>
      <geometry>
        <mesh filename="package://hera_description/meshes/panda/collision/link3.stl"/>
      </geometry>
    </collision>
    <inertial>
      <origin rpy="0 0 0" xyz="0 0 0"/>
      <mass value="2.38"/>
      <inertia ixx="0.3" ixy="0.0" ixz="0.0" iyy="0.3" iyz="0.0" izz="0.3"/>
    </inertial>
  </link>
  <!-- joint between link 3 and link 4 -->
  <joint name="panda_joint_4" type="revolute">
    <safety_controller k_position="100.0" k_velocity="40.0" soft_lower_limit="-3.0718" soft_upper_limit="-0.0698"/>
    <origin rpy="1.5707963267948966 0 0" xyz="0.0825 0 0"/>
    <parent link="panda_link_3"/>
    <child link="panda_link_4"/>
    <axis xyz="0 0 1"/>
    <limit effort="87" lower="-3.0718" upper="-0.0698" velocity="2.1750"/>
    <dynamics damping="1.0"/>
  </joint>
  <!-- link 4 -->
  <link name="panda_link_4">
    <visual>
      <geometry>
        <mesh filename="package://hera_description/meshes/panda/visual/link4.dae"/>
      </geometry>
    </visual>
    <collision>
      <geometry>
        <mesh filename="package://hera_description/meshes/panda/collision/link4.stl"/>
      </geometry>
    </collision>
    <inertial>
      <origin rpy="0 0 0" xyz="0 0 0"/>
      <mass value="2.43"/>
      <inertia ixx="0.3" ixy="0.0" ixz="0.0" iyy="0.3" iyz="0.0" izz="0.3"/>
    </inertial>
  </link>
  <!-- joint between link 4 and link 5 -->
  <joint name="panda_joint_5" type="revolute">
    <safety_controller k_position="100.0" k_velocity="40.0" soft_lower_limit="-2.8973" soft_upper_limit="2.8973"/>
    <origin rpy="-1.5707963267948966 0 0" xyz="-0.0825 0.384 0"/>
    <parent link="panda_link_4"/>
    <child link="panda_link_5"/>
    <axis xyz="0 0 1"/>
    <limit effort="12" lower="-2.8973" upper="2.8973" velocity="2.6100"/>
    <dynamics damping="1.0"/>
  </joint>
  <!-- link 5 -->
  <link name="panda_link_5">
    <visual>
      <geometry>
        <mesh filename="package://hera_description/meshes/panda/visual/link5.dae"/>
      </geometry>
    </visual>
    <collision>
      <geometry>
        <mesh filename="package://hera_description/meshes/panda/collision/link5.stl"/>
      </geometry>
    </collision>
    <inertial>
      <origin rpy="0 0 0" xyz="0 0 0"/>
      <mass value="3.5"/>
      <inertia ixx="0.3" ixy="0.0" ixz="0.0" iyy="0.3" iyz="0.0" izz="0.3"/>
    </inertial>
  </link>
  <!-- joint between link 5 and link 6 -->
  <joint name="panda_joint_6" type="revolute">
    <safety_controller k_position="100.0" k_velocity="40.0" soft_lower_limit="-3.0175" soft_upper_limit="3.7525"/>
    <origin rpy="1.5707963267948966 0 0" xyz="0 0 0"/>
    <parent link="panda_link_5"/>
    <child link="panda_link_6"/>
    <axis xyz="0 0 1"/>
    <limit effort="12" lower="-3.0175" upper="3.7525" velocity="2.6100"/>
    <dynamics damping="1.0"/>
  </joint>
  <!-- link 6 -->
  <link name="panda_link_6">
    <visual>
      <geometry>
        <mesh filename="package://hera_description/meshes/panda/visual/link6.dae"/>
      </geometry>
    </visual>
    <collision>
      <geometry>
        <mesh filename="package://hera_description/meshes/panda/collision/link6.stl"/>
      </geometry>
    </collision>
    <inertial>
      <origin rpy="0 0 0" xyz="0 0 0"/>
      <mass value="1.47"/>
      <inertia ixx="0.3" ixy="0.0" ixz="0.0" iyy="0.3" iyz="0.0" izz="0.3"/>
    </inertial>
  </link>
  <!-- joint between link 6 and link 7 -->
  <joint name="panda_joint_7" type="revolute">
    <safety_controller k_position="100.0" k_velocity="40.0" soft_lower_limit="-2.8973" soft_upper_limit="2.8973"/>
    <origin rpy="1.5707963267948966 0 0" xyz="0.088 0 0"/>
    <parent link="panda_link_6"/>
    <child link="panda_link_7"/>
    <axis xyz="0 0 1"/>
    <limit effort="12" lower="-2.8973" upper="2.8973" velocity="2.6100"/>
    <dynamics damping="1.0"/>
  </joint>
  <!-- link 7 -->
  <link name="panda_link_7">
    <visual>
      <geometry>
        <mesh filename="package://hera_description/meshes/panda/visual/link7.dae"/>
      </geometry>
    </visual>
    <collision>
      <geometry>
        <mesh filename="package://hera_description/meshes/panda/collision/link7.stl"/>
      </geometry>
    </collision>
    <inertial>
      <origin rpy="0 0 0" xyz="0 0 0"/>
      <mass value="0.45"/>
      <inertia ixx="0.3" ixy="0.0" ixz="0.0" iyy="0.3" iyz="0.0" izz="0.3"/>
    </inertial>
  </link>
  <!-- joint between link 7 and end-effector -->
  <joint name="panda_joint_ee" type="fixed">
    <origin rpy="0 0 0" xyz="0 0 0.107"/>
    <parent link="panda_link_7"/>
    <child link="panda_link_ee"/>
    <axis xyz="0 0 0"/>
  </joint>
  <!-- end-effector link -->
  <link name="panda_link_ee">
    <inertial>
      <origin rpy="0 0 0" xyz="0 0 0"/>
      <mass value="1.0"/>
      <inertia ixx="1.0" ixy="0.0" ixz="0.0" iyy="1.0" iyz="0.0" izz="1.0"/>
    </inertial>
  </link>
  <!-- Load Gazebo lib and set the robot namespace -->
  <gazebo>
    <plugin filename="libgazebo_ros_control.so" name="gazebo_ros_control">
      <robotNamespace>/panda</robotNamespace>
      <legacyModeNS>true</legacyModeNS>
    </plugin>
  </gazebo>
  <!-- Link0 -->
  <gazebo reference="panda_link_0">
    <mu1>0.61</mu1>
    <mu2>0.61</mu2>
  </gazebo>
  <!-- Link1 -->
  <gazebo reference="panda_link_1">
    <mu1>0.61</mu1>
    <mu2>0.61</mu2>
  </gazebo>
  <!-- Link2 -->
  <gazebo reference="panda_link_2">
    <mu1>0.61</mu1>
    <mu2>0.61</mu2>
  </gazebo>
  <!-- Link3 -->
  <gazebo reference="panda_link_3">
    <mu1>0.61</mu1>
    <mu2>0.61</mu2>
  </gazebo>
  <!-- Link4 -->
  <gazebo reference="panda_link_4">
    <mu1>0.61</mu1>
    <mu2>0.61</mu2>
  </gazebo>
  <!-- Link5 -->
  <gazebo reference="panda_link_5">
    <mu1>0.61</mu1>
    <mu2>0.61</mu2>
  </gazebo>
  <!-- Link6 -->
  <gazebo reference="panda_link_6">
    <mu1>0.61</mu1>
    <mu2>0.61</mu2>
  </gazebo>
  <!-- Link7 -->
  <gazebo reference="panda_link_7">
    <mu1>0.61</mu1>
    <mu2>0.61</mu2>
  </gazebo>
  <transmission name="panda_tran_1">
    <robotNamespace>/panda</robotNamespace>
    <type>transmission_interface/SimpleTransmission</type>
    <joint name="panda_joint_1">
      <hardwareInterface>hardware_interface/PositionJointInterface</hardwareInterface>
    </joint>
    <actuator name="panda_motor_1">
      <hardwareInterface>PositionJointInterface</hardwareInterface>
      <mechanicalReduction>1</mechanicalReduction>
    </actuator>
  </transmission>
  <transmission name="panda_tran_2">
    <robotNamespace>/panda</robotNamespace>
    <type>transmission_interface/SimpleTransmission</type>
    <joint name="panda_joint_2">
      <hardwareInterface>hardware_interface/PositionJointInterface</hardwareInterface>
    </joint>
    <actuator name="panda_motor_2">
      <hardwareInterface>PositionJointInterface</hardwareInterface>
      <mechanicalReduction>1</mechanicalReduction>
    </actuator>
  </transmission>
  <transmission name="panda_tran_3">
    <robotNamespace>/panda</robotNamespace>
    <type>transmission_interface/SimpleTransmission</type>
    <joint name="panda_joint_3">
      <hardwareInterface>hardware_interface/PositionJointInterface</hardwareInterface>
    </joint>
    <actuator name="panda_motor_3">
      <hardwareInterface>PositionJointInterface</hardwareInterface>
      <mechanicalReduction>1</mechanicalReduction>
    </actuator>
  </transmission>
  <transmission name="panda_tran_4">
    <robotNamespace>/panda</robotNamespace>
    <type>transmission_interface/SimpleTransmission</type>
    <joint name="panda_joint_4">
      <hardwareInterface>hardware_interface/PositionJointInterface</hardwareInterface>
    </joint>
    <actuator name="panda_motor_4">
      <hardwareInterface>PositionJointInterface</hardwareInterface>
      <mechanicalReduction>1</mechanicalReduction>
    </actuator>
  </transmission>
  <transmission name="panda_tran_5">
    <robotNamespace>/panda</robotNamespace>
    <type>transmission_interface/SimpleTransmission</type>
    <joint name="panda_joint_5">
      <hardwareInterface>hardware_interface/PositionJointInterface</hardwareInterface>
    </joint>
    <actuator name="panda_motor_5">
      <hardwareInterface>PositionJointInterface</hardwareInterface>
      <mechanicalReduction>1</mechanicalReduction>
    </actuator>
  </transmission>
  <transmission name="panda_tran_6">
    <robotNamespace>/panda</robotNamespace>
    <type>transmission_interface/SimpleTransmission</type>
    <joint name="panda_joint_6">
      <hardwareInterface>hardware_interface/PositionJointInterface</hardwareInterface>
    </joint>
    <actuator name="panda_motor_6">
      <hardwareInterface>PositionJointInterface</hardwareInterface>
      <mechanicalReduction>1</mechanicalReduction>
    </actuator>
  </transmission>
  <transmission name="panda_tran_7">
    <robotNamespace>/panda</robotNamespace>
    <type>transmission_interface/SimpleTransmission</type>
    <joint name="panda_joint_7">
      <hardwareInterface>hardware_interface/PositionJointInterface</hardwareInterface>
    </joint>
    <actuator name="panda_motor_7">
      <hardwareInterface>PositionJointInterface</hardwareInterface>
      <mechanicalReduction>1</mechanicalReduction>
    </actuator>
  </transmission>
  <!--joint between {parent} and camera head-->
  <joint name="panda_link_ee_milc_joint" type="fixed">
    <parent link="panda_link_ee"/>
    <child link="panda_milc_head"/>
    <origin rpy="0 0 0.7853981633974483" xyz="0 0 0"/>
  </joint>
  <!-- camera head link -->
  <link name="panda_milc_head">
    <visual>
      <geometry>
        <mesh filename="package://hera_description/meshes/milc/visual/milc_head_colorized.dae" scale="0.01 0.01 0.01"/>
      </geometry>
    </visual>
    <collision>
      <geometry>
        <mesh filename="package://hera_description/meshes/milc/collision/milc_head_convex.stl" scale="0.01 0.01 0.01"/>
      </geometry>
    </collision>
    <!-- TODO: change these values!! -->
    <inertial>
      <origin rpy="0 0 0" xyz="0 0 0"/>
      <mass value="0.0001"/>
      <inertia ixx="0.0" ixy="0" ixz="0" iyy="0.0" iyz="0" izz="0.0"/>
    </inertial>
  </link>
  <!-- joint between camera head and optics -->
  <joint name="panda_milc_optics_joint" type="revolute">
    <!-- TODO: change these values!! -->
    <safety_controller k_position="100.0" k_velocity="40.0" soft_lower_limit="-2.8973" soft_upper_limit="2.8973"/>
    <origin rpy="0 0 0" xyz="0 0 0.133551"/>
    <parent link="panda_milc_head"/>
    <child link="panda_milc_optics"/>
    <axis xyz="0 0 1"/>
    <!-- TODO: change these values!! -->
    <limit effort="87" lower="-2.8973" upper="2.8973" velocity="2.1750"/>
  </joint>
  <!-- optics link -->
  <link name="panda_milc_optics">
    <visual>
      <geometry>
        <mesh filename="package://hera_description/meshes/milc/visual/milc_optics_colorized.dae" scale="0.01 0.01 0.01"/>
      </geometry>
    </visual>
    <collision>
      <geometry>
        <mesh filename="package://hera_description/meshes/milc/collision/milc_optics_convex.stl" scale="0.01 0.01 0.01"/>
      </geometry>
    </collision>
    <!-- TODO: change these values!! -->
    <inertial>
      <origin rpy="0 0 0" xyz="0 0 0"/>
      <mass value="0.0001"/>
      <inertia ixx="0.0" ixy="0" ixz="0" iyy="0.0" iyz="0" izz="0.0"/>
    </inertial>
  </link>
  <!-- Flange link -->
  <joint name="panda_milc_optics_flange_joint" type="fixed">
    <parent link="panda_milc_head"/>
    <child link="panda_milc_link_optics_flange"/>
    <!-- TODO: change me -->
    <origin rpy="0 0 0" xyz="0 0 0.133551"/>
  </joint>
  <link name="panda_milc_link_optics_flange">
    <!-- TODO: change these values!! -->
    <inertial>
      <origin rpy="0 0 0" xyz="0 0 0"/>
      <mass value="0.0001"/>
      <inertia ixx="0.0" ixy="0" ixz="0" iyy="0.0" iyz="0" izz="0.0"/>
    </inertial>
  </link>
  <!-- TCP link -->
  <joint name="panda_milc_ee_joint" type="fixed">
    <parent link="panda_milc_optics"/>
    <child link="panda_milc_link_ee"/>
    <!-- TODO: change me -->
    <origin rpy="0 0 0" xyz="0 0 0.385138"/>
  </joint>
  <link name="panda_milc_link_ee">
    <!-- TODO: change these values!! -->
    <inertial>
      <origin rpy="0 0 0" xyz="0 0 0"/>
      <mass value="0.0001"/>
      <inertia ixx="0.0" ixy="0" ixz="0" iyy="0.0" iyz="0" izz="0.0"/>
    </inertial>
  </link>
  <!-- view cone link -->
  <joint name="panda_milc_cone_joint" type="fixed">
    <parent link="panda_milc_link_ee"/>
    <child link="panda_milc_cone"/>
    <!-- TODO: change me -->
    <origin rpy="0 0 0" xyz="0 0 0.0"/>
  </joint>
  <link name="panda_milc_cone">
    <visual>
      <geometry>
        <mesh filename="package://hera_description/meshes/milc/visual/view_cone.dae" scale="0.02 0.02 0.02"/>
      </geometry>
    </visual>
    <!-- TODO: change these values!! -->
    <inertial>
      <origin rpy="0 0 0" xyz="0 0 0"/>
      <mass value="0.0001"/>
      <inertia ixx="0.0" ixy="0" ixz="0" iyy="0.0" iyz="0" izz="0.0"/>
    </inertial>
  </link>
  <!-- Load Gazebo lib and set the robot namespace
    <gazebo>
      <plugin name="gazebo_ros_control" filename="libgazebo_ros_control.so">
        <legacyModeNS>true</legacyModeNS>
      </plugin>
    </gazebo -->
  <!-- camera head link -->
  <gazebo reference="panda_milc_head">
    <mu1>0.2</mu1>
    <mu2>0.2</mu2>
  </gazebo>
  <!-- optics link -->
  <gazebo reference="panda_milc_optics">
    <mu1>0.2</mu1>
    <mu2>0.2</mu2>
  </gazebo>
  <!-- end effector link -->
  <gazebo reference="panda_milc_link_ee">
    <mu1>0.2</mu1>
    <mu2>0.2</mu2>
  </gazebo>
  <!-- Flange link -->
  <gazebo reference="panda_milc_link_optics_flange">
    <mu1>0.2</mu1>
    <mu2>0.2</mu2>
  </gazebo>
  <transmission name="panda_milc_optics_tran_1">
    <type>transmission_interface/SimpleTransmission</type>
    <joint name="panda_milc_optics_joint">
      <hardwareInterface>hardware_interface/PositionJointInterface</hardwareInterface>
    </joint>
    <actuator name="panda_milc_optics_motor">
      <hardwareInterface>PositionJointInterface</hardwareInterface>
      <mechanicalReduction>1</mechanicalReduction>
    </actuator>
  </transmission>
  <!-- Do noting in case of none -->
  <!-- Link Table 
    <gazebo reference="table">
      <mu1>100.0</mu1>
      <mu2>100.0</mu2>
      <kp>1000000.0</kp>
      <kd>1.0</kd>
      <fdir1>1 0 0</fdir1>
      <minDepth>0.001</minDepth>
      # <static>true</static> 
    </gazebo>
    -->
  <gazebo reference="panda_link_0">
    <static>true</static>
  </gazebo>
</robot>

